The solution involves using a `.catch()` block to handle the rejected promise.

```javascript
AsyncStorage.setItem('myKey', 'myValue')
  .then(() => {
    console.log('Value set!');
  })
  .catch(error => {
    console.error('Error setting value:', error);
    // Handle the error appropriately, e.g., display an alert to the user.
  });

// Example with getItem:
AsyncStorage.getItem('myKey')
  .then(value => {
    console.log('Value retrieved:', value);
  })
  .catch(error => {
    console.error('Error retrieving value:', error);
    // Handle error, e.g., display a default value or message.
  });
```

This improved code handles both successful and unsuccessful scenarios, making the application more robust and preventing unexpected crashes due to unhandled promise rejections.